{
 "cells": [
  {
   "cell_type": "code",
   "execution_count": 23,
   "id": "6553ca99",
   "metadata": {},
   "outputs": [],
   "source": [
    "import os\n",
    "import cv2\n",
    "import numpy as np\n",
    "import tensorflow as tf\n",
    "from tensorflow.keras.applications import ResNet50\n",
    "from tensorflow.keras.layers import Conv2DTranspose"
   ]
  },
  {
   "cell_type": "code",
   "execution_count": 24,
   "id": "29ea0afc",
   "metadata": {},
   "outputs": [],
   "source": [
    "class CustomDataset(tf.keras.utils.Sequence):\n",
    "    def __init__(self, images_dir, annotations_dir, batch_size=32, image_size=(128, 128), shuffle=True):\n",
    "        self.images_dir = images_dir\n",
    "        self.annotations_dir = annotations_dir\n",
    "        self.batch_size = batch_size\n",
    "        self.image_size = image_size\n",
    "        self.shuffle = shuffle\n",
    "\n",
    "        self.image_paths = sorted(os.listdir(self.images_dir))\n",
    "        self.annotation_paths = sorted(os.listdir(self.annotations_dir))\n",
    "\n",
    "        self.indexes = np.arange(len(self.image_paths))\n",
    "        if self.shuffle:\n",
    "            np.random.shuffle(self.indexes)\n",
    "\n",
    "    def __len__(self):\n",
    "        return int(np.ceil(len(self.image_paths) / self.batch_size))\n",
    "\n",
    "    def __getitem__(self, index):\n",
    "        batch_indexes = self.indexes[index * self.batch_size : (index + 1) * self.batch_size]\n",
    "\n",
    "        batch_images = []\n",
    "        batch_annotations = []\n",
    "\n",
    "        for i in batch_indexes:\n",
    "            image_path = os.path.join(self.images_dir, self.image_paths[i])\n",
    "            annotation_path = os.path.join(self.annotations_dir, self.annotation_paths[i])\n",
    "\n",
    "            image = cv2.imread(image_path)\n",
    "            annotation = cv2.imread(annotation_path, cv2.IMREAD_GRAYSCALE)\n",
    "            image = cv2.resize(image, self.image_size)\n",
    "            annotation = cv2.resize(annotation, self.image_size)\n",
    "            image = image.astype(np.float32) / 255.0\n",
    "\n",
    "            batch_images.append(image)\n",
    "            batch_annotations.append(annotation)\n",
    "\n",
    "        return np.array(batch_images), np.array(batch_annotations)"
   ]
  },
  {
   "cell_type": "code",
   "execution_count": 25,
   "id": "79e4dfad",
   "metadata": {},
   "outputs": [],
   "source": [
    "images_dir = r\"C:\\Users\\dharu\\OneDrive\\Desktop\\6th Semester\\Machine Learning\\test\\images\\test\\t5\"\n",
    "annotations_dir = r\"C:\\Users\\dharu\\OneDrive\\Desktop\\6th Semester\\Machine Learning\\test\\annotations\\test\\t5\""
   ]
  },
  {
   "cell_type": "code",
   "execution_count": 30,
   "id": "2283956b",
   "metadata": {},
   "outputs": [],
   "source": [
    "train_dataset = CustomDataset(images_dir, annotations_dir, batch_size=32, image_size=(128, 128), shuffle=True)"
   ]
  },
  {
   "cell_type": "code",
   "execution_count": 31,
   "id": "d7a28d8f",
   "metadata": {},
   "outputs": [],
   "source": [
    "import os\n",
    "import cv2\n",
    "import numpy as np\n",
    "import tensorflow as tf\n",
    "from tensorflow.keras.applications import ResNet50\n",
    "from tensorflow.keras.layers import Conv2DTranspose"
   ]
  },
  {
   "cell_type": "code",
   "execution_count": 32,
   "id": "2172ce41",
   "metadata": {},
   "outputs": [],
   "source": [
    "def create_segmentation_model(input_shape, num_classes):\n",
    "    base_model = ResNet50(input_shape=input_shape, include_top=False)\n",
    "    x = base_model.output\n",
    "    x = Conv2DTranspose(256, kernel_size=(3, 3), strides=(2, 2), padding='same')(x)\n",
    "    x = Conv2DTranspose(128, kernel_size=(3, 3), strides=(2, 2), padding='same')(x)\n",
    "    x = Conv2DTranspose(num_classes, kernel_size=(1, 1), padding='same', activation='softmax')(x)\n",
    "    model = tf.keras.Model(inputs=base_model.input, outputs=x)\n",
    "    return model"
   ]
  },
  {
   "cell_type": "code",
   "execution_count": 33,
   "id": "f88851bd",
   "metadata": {},
   "outputs": [],
   "source": [
    "batch_size = 32\n",
    "image_size = (128, 128)  \n",
    "input_shape = (image_size[0], image_size[1], 3)  \n",
    "num_classes = 3\n",
    "segmentation_model = create_segmentation_model(input_shape, num_classes)"
   ]
  },
  {
   "cell_type": "code",
   "execution_count": 34,
   "id": "4e557bdb",
   "metadata": {},
   "outputs": [],
   "source": [
    "segmentation_model.compile(optimizer='adam', loss='sparse_categorical_crossentropy', metrics=['accuracy'])"
   ]
  },
  {
   "cell_type": "code",
   "execution_count": 35,
   "id": "927b5ff9",
   "metadata": {},
   "outputs": [
    {
     "name": "stdout",
     "output_type": "stream",
     "text": [
      "Epoch 1/10\n"
     ]
    },
    {
     "ename": "InvalidArgumentError",
     "evalue": "Graph execution error:\n\nDetected at node sparse_categorical_crossentropy/SparseSoftmaxCrossEntropyWithLogits/assert_equal_1/Assert/Assert defined at (most recent call last):\n  File \"C:\\Users\\dharu\\anaconda3\\lib\\runpy.py\", line 197, in _run_module_as_main\n\n  File \"C:\\Users\\dharu\\anaconda3\\lib\\runpy.py\", line 87, in _run_code\n\n  File \"C:\\Users\\dharu\\anaconda3\\lib\\site-packages\\ipykernel_launcher.py\", line 17, in <module>\n\n  File \"C:\\Users\\dharu\\anaconda3\\lib\\site-packages\\traitlets\\config\\application.py\", line 846, in launch_instance\n\n  File \"C:\\Users\\dharu\\anaconda3\\lib\\site-packages\\ipykernel\\kernelapp.py\", line 712, in start\n\n  File \"C:\\Users\\dharu\\anaconda3\\lib\\site-packages\\tornado\\platform\\asyncio.py\", line 199, in start\n\n  File \"C:\\Users\\dharu\\anaconda3\\lib\\asyncio\\base_events.py\", line 601, in run_forever\n\n  File \"C:\\Users\\dharu\\anaconda3\\lib\\asyncio\\base_events.py\", line 1905, in _run_once\n\n  File \"C:\\Users\\dharu\\anaconda3\\lib\\asyncio\\events.py\", line 80, in _run\n\n  File \"C:\\Users\\dharu\\anaconda3\\lib\\site-packages\\ipykernel\\kernelbase.py\", line 510, in dispatch_queue\n\n  File \"C:\\Users\\dharu\\anaconda3\\lib\\site-packages\\ipykernel\\kernelbase.py\", line 499, in process_one\n\n  File \"C:\\Users\\dharu\\anaconda3\\lib\\site-packages\\ipykernel\\kernelbase.py\", line 406, in dispatch_shell\n\n  File \"C:\\Users\\dharu\\anaconda3\\lib\\site-packages\\ipykernel\\kernelbase.py\", line 730, in execute_request\n\n  File \"C:\\Users\\dharu\\anaconda3\\lib\\site-packages\\ipykernel\\ipkernel.py\", line 390, in do_execute\n\n  File \"C:\\Users\\dharu\\anaconda3\\lib\\site-packages\\ipykernel\\zmqshell.py\", line 528, in run_cell\n\n  File \"C:\\Users\\dharu\\anaconda3\\lib\\site-packages\\IPython\\core\\interactiveshell.py\", line 2914, in run_cell\n\n  File \"C:\\Users\\dharu\\anaconda3\\lib\\site-packages\\IPython\\core\\interactiveshell.py\", line 2960, in _run_cell\n\n  File \"C:\\Users\\dharu\\anaconda3\\lib\\site-packages\\IPython\\core\\async_helpers.py\", line 78, in _pseudo_sync_runner\n\n  File \"C:\\Users\\dharu\\anaconda3\\lib\\site-packages\\IPython\\core\\interactiveshell.py\", line 3185, in run_cell_async\n\n  File \"C:\\Users\\dharu\\anaconda3\\lib\\site-packages\\IPython\\core\\interactiveshell.py\", line 3377, in run_ast_nodes\n\n  File \"C:\\Users\\dharu\\anaconda3\\lib\\site-packages\\IPython\\core\\interactiveshell.py\", line 3457, in run_code\n\n  File \"C:\\Users\\dharu\\AppData\\Local\\Temp\\ipykernel_30880\\222387833.py\", line 1, in <module>\n\n  File \"C:\\Users\\dharu\\anaconda3\\lib\\site-packages\\keras\\src\\utils\\traceback_utils.py\", line 65, in error_handler\n\n  File \"C:\\Users\\dharu\\anaconda3\\lib\\site-packages\\keras\\src\\engine\\training.py\", line 1807, in fit\n\n  File \"C:\\Users\\dharu\\anaconda3\\lib\\site-packages\\keras\\src\\engine\\training.py\", line 1401, in train_function\n\n  File \"C:\\Users\\dharu\\anaconda3\\lib\\site-packages\\keras\\src\\engine\\training.py\", line 1384, in step_function\n\n  File \"C:\\Users\\dharu\\anaconda3\\lib\\site-packages\\keras\\src\\engine\\training.py\", line 1373, in run_step\n\n  File \"C:\\Users\\dharu\\anaconda3\\lib\\site-packages\\keras\\src\\engine\\training.py\", line 1151, in train_step\n\n  File \"C:\\Users\\dharu\\anaconda3\\lib\\site-packages\\keras\\src\\engine\\training.py\", line 1209, in compute_loss\n\n  File \"C:\\Users\\dharu\\anaconda3\\lib\\site-packages\\keras\\src\\engine\\compile_utils.py\", line 277, in __call__\n\n  File \"C:\\Users\\dharu\\anaconda3\\lib\\site-packages\\keras\\src\\losses.py\", line 143, in __call__\n\n  File \"C:\\Users\\dharu\\anaconda3\\lib\\site-packages\\keras\\src\\losses.py\", line 270, in call\n\n  File \"C:\\Users\\dharu\\anaconda3\\lib\\site-packages\\keras\\src\\losses.py\", line 2454, in sparse_categorical_crossentropy\n\n  File \"C:\\Users\\dharu\\anaconda3\\lib\\site-packages\\keras\\src\\backend.py\", line 5775, in sparse_categorical_crossentropy\n\nassertion failed: [Condition x == y did not hold element-wise:] [x (sparse_categorical_crossentropy/SparseSoftmaxCrossEntropyWithLogits/Shape_1:0) = ] [32 128 128] [y (sparse_categorical_crossentropy/SparseSoftmaxCrossEntropyWithLogits/strided_slice:0) = ] [32 16 16]\n\t [[{{node sparse_categorical_crossentropy/SparseSoftmaxCrossEntropyWithLogits/assert_equal_1/Assert/Assert}}]] [Op:__inference_train_function_113039]",
     "output_type": "error",
     "traceback": [
      "\u001b[1;31m---------------------------------------------------------------------------\u001b[0m",
      "\u001b[1;31mInvalidArgumentError\u001b[0m                      Traceback (most recent call last)",
      "\u001b[1;32m~\\AppData\\Local\\Temp\\ipykernel_30880\\222387833.py\u001b[0m in \u001b[0;36m<module>\u001b[1;34m\u001b[0m\n\u001b[1;32m----> 1\u001b[1;33m \u001b[0msegmentation_model\u001b[0m\u001b[1;33m.\u001b[0m\u001b[0mfit\u001b[0m\u001b[1;33m(\u001b[0m\u001b[0mtrain_dataset\u001b[0m\u001b[1;33m,\u001b[0m \u001b[0mepochs\u001b[0m\u001b[1;33m=\u001b[0m\u001b[1;36m10\u001b[0m\u001b[1;33m)\u001b[0m\u001b[1;33m\u001b[0m\u001b[1;33m\u001b[0m\u001b[0m\n\u001b[0m",
      "\u001b[1;32m~\\anaconda3\\lib\\site-packages\\keras\\src\\utils\\traceback_utils.py\u001b[0m in \u001b[0;36merror_handler\u001b[1;34m(*args, **kwargs)\u001b[0m\n\u001b[0;32m     68\u001b[0m             \u001b[1;31m# To get the full stack trace, call:\u001b[0m\u001b[1;33m\u001b[0m\u001b[1;33m\u001b[0m\u001b[0m\n\u001b[0;32m     69\u001b[0m             \u001b[1;31m# `tf.debugging.disable_traceback_filtering()`\u001b[0m\u001b[1;33m\u001b[0m\u001b[1;33m\u001b[0m\u001b[0m\n\u001b[1;32m---> 70\u001b[1;33m             \u001b[1;32mraise\u001b[0m \u001b[0me\u001b[0m\u001b[1;33m.\u001b[0m\u001b[0mwith_traceback\u001b[0m\u001b[1;33m(\u001b[0m\u001b[0mfiltered_tb\u001b[0m\u001b[1;33m)\u001b[0m \u001b[1;32mfrom\u001b[0m \u001b[1;32mNone\u001b[0m\u001b[1;33m\u001b[0m\u001b[1;33m\u001b[0m\u001b[0m\n\u001b[0m\u001b[0;32m     71\u001b[0m         \u001b[1;32mfinally\u001b[0m\u001b[1;33m:\u001b[0m\u001b[1;33m\u001b[0m\u001b[1;33m\u001b[0m\u001b[0m\n\u001b[0;32m     72\u001b[0m             \u001b[1;32mdel\u001b[0m \u001b[0mfiltered_tb\u001b[0m\u001b[1;33m\u001b[0m\u001b[1;33m\u001b[0m\u001b[0m\n",
      "\u001b[1;32m~\\anaconda3\\lib\\site-packages\\tensorflow\\python\\eager\\execute.py\u001b[0m in \u001b[0;36mquick_execute\u001b[1;34m(op_name, num_outputs, inputs, attrs, ctx, name)\u001b[0m\n\u001b[0;32m     51\u001b[0m   \u001b[1;32mtry\u001b[0m\u001b[1;33m:\u001b[0m\u001b[1;33m\u001b[0m\u001b[1;33m\u001b[0m\u001b[0m\n\u001b[0;32m     52\u001b[0m     \u001b[0mctx\u001b[0m\u001b[1;33m.\u001b[0m\u001b[0mensure_initialized\u001b[0m\u001b[1;33m(\u001b[0m\u001b[1;33m)\u001b[0m\u001b[1;33m\u001b[0m\u001b[1;33m\u001b[0m\u001b[0m\n\u001b[1;32m---> 53\u001b[1;33m     tensors = pywrap_tfe.TFE_Py_Execute(ctx._handle, device_name, op_name,\n\u001b[0m\u001b[0;32m     54\u001b[0m                                         inputs, attrs, num_outputs)\n\u001b[0;32m     55\u001b[0m   \u001b[1;32mexcept\u001b[0m \u001b[0mcore\u001b[0m\u001b[1;33m.\u001b[0m\u001b[0m_NotOkStatusException\u001b[0m \u001b[1;32mas\u001b[0m \u001b[0me\u001b[0m\u001b[1;33m:\u001b[0m\u001b[1;33m\u001b[0m\u001b[1;33m\u001b[0m\u001b[0m\n",
      "\u001b[1;31mInvalidArgumentError\u001b[0m: Graph execution error:\n\nDetected at node sparse_categorical_crossentropy/SparseSoftmaxCrossEntropyWithLogits/assert_equal_1/Assert/Assert defined at (most recent call last):\n  File \"C:\\Users\\dharu\\anaconda3\\lib\\runpy.py\", line 197, in _run_module_as_main\n\n  File \"C:\\Users\\dharu\\anaconda3\\lib\\runpy.py\", line 87, in _run_code\n\n  File \"C:\\Users\\dharu\\anaconda3\\lib\\site-packages\\ipykernel_launcher.py\", line 17, in <module>\n\n  File \"C:\\Users\\dharu\\anaconda3\\lib\\site-packages\\traitlets\\config\\application.py\", line 846, in launch_instance\n\n  File \"C:\\Users\\dharu\\anaconda3\\lib\\site-packages\\ipykernel\\kernelapp.py\", line 712, in start\n\n  File \"C:\\Users\\dharu\\anaconda3\\lib\\site-packages\\tornado\\platform\\asyncio.py\", line 199, in start\n\n  File \"C:\\Users\\dharu\\anaconda3\\lib\\asyncio\\base_events.py\", line 601, in run_forever\n\n  File \"C:\\Users\\dharu\\anaconda3\\lib\\asyncio\\base_events.py\", line 1905, in _run_once\n\n  File \"C:\\Users\\dharu\\anaconda3\\lib\\asyncio\\events.py\", line 80, in _run\n\n  File \"C:\\Users\\dharu\\anaconda3\\lib\\site-packages\\ipykernel\\kernelbase.py\", line 510, in dispatch_queue\n\n  File \"C:\\Users\\dharu\\anaconda3\\lib\\site-packages\\ipykernel\\kernelbase.py\", line 499, in process_one\n\n  File \"C:\\Users\\dharu\\anaconda3\\lib\\site-packages\\ipykernel\\kernelbase.py\", line 406, in dispatch_shell\n\n  File \"C:\\Users\\dharu\\anaconda3\\lib\\site-packages\\ipykernel\\kernelbase.py\", line 730, in execute_request\n\n  File \"C:\\Users\\dharu\\anaconda3\\lib\\site-packages\\ipykernel\\ipkernel.py\", line 390, in do_execute\n\n  File \"C:\\Users\\dharu\\anaconda3\\lib\\site-packages\\ipykernel\\zmqshell.py\", line 528, in run_cell\n\n  File \"C:\\Users\\dharu\\anaconda3\\lib\\site-packages\\IPython\\core\\interactiveshell.py\", line 2914, in run_cell\n\n  File \"C:\\Users\\dharu\\anaconda3\\lib\\site-packages\\IPython\\core\\interactiveshell.py\", line 2960, in _run_cell\n\n  File \"C:\\Users\\dharu\\anaconda3\\lib\\site-packages\\IPython\\core\\async_helpers.py\", line 78, in _pseudo_sync_runner\n\n  File \"C:\\Users\\dharu\\anaconda3\\lib\\site-packages\\IPython\\core\\interactiveshell.py\", line 3185, in run_cell_async\n\n  File \"C:\\Users\\dharu\\anaconda3\\lib\\site-packages\\IPython\\core\\interactiveshell.py\", line 3377, in run_ast_nodes\n\n  File \"C:\\Users\\dharu\\anaconda3\\lib\\site-packages\\IPython\\core\\interactiveshell.py\", line 3457, in run_code\n\n  File \"C:\\Users\\dharu\\AppData\\Local\\Temp\\ipykernel_30880\\222387833.py\", line 1, in <module>\n\n  File \"C:\\Users\\dharu\\anaconda3\\lib\\site-packages\\keras\\src\\utils\\traceback_utils.py\", line 65, in error_handler\n\n  File \"C:\\Users\\dharu\\anaconda3\\lib\\site-packages\\keras\\src\\engine\\training.py\", line 1807, in fit\n\n  File \"C:\\Users\\dharu\\anaconda3\\lib\\site-packages\\keras\\src\\engine\\training.py\", line 1401, in train_function\n\n  File \"C:\\Users\\dharu\\anaconda3\\lib\\site-packages\\keras\\src\\engine\\training.py\", line 1384, in step_function\n\n  File \"C:\\Users\\dharu\\anaconda3\\lib\\site-packages\\keras\\src\\engine\\training.py\", line 1373, in run_step\n\n  File \"C:\\Users\\dharu\\anaconda3\\lib\\site-packages\\keras\\src\\engine\\training.py\", line 1151, in train_step\n\n  File \"C:\\Users\\dharu\\anaconda3\\lib\\site-packages\\keras\\src\\engine\\training.py\", line 1209, in compute_loss\n\n  File \"C:\\Users\\dharu\\anaconda3\\lib\\site-packages\\keras\\src\\engine\\compile_utils.py\", line 277, in __call__\n\n  File \"C:\\Users\\dharu\\anaconda3\\lib\\site-packages\\keras\\src\\losses.py\", line 143, in __call__\n\n  File \"C:\\Users\\dharu\\anaconda3\\lib\\site-packages\\keras\\src\\losses.py\", line 270, in call\n\n  File \"C:\\Users\\dharu\\anaconda3\\lib\\site-packages\\keras\\src\\losses.py\", line 2454, in sparse_categorical_crossentropy\n\n  File \"C:\\Users\\dharu\\anaconda3\\lib\\site-packages\\keras\\src\\backend.py\", line 5775, in sparse_categorical_crossentropy\n\nassertion failed: [Condition x == y did not hold element-wise:] [x (sparse_categorical_crossentropy/SparseSoftmaxCrossEntropyWithLogits/Shape_1:0) = ] [32 128 128] [y (sparse_categorical_crossentropy/SparseSoftmaxCrossEntropyWithLogits/strided_slice:0) = ] [32 16 16]\n\t [[{{node sparse_categorical_crossentropy/SparseSoftmaxCrossEntropyWithLogits/assert_equal_1/Assert/Assert}}]] [Op:__inference_train_function_113039]"
     ]
    }
   ],
   "source": [
    "segmentation_model.fit(train_dataset, epochs=10)"
   ]
  },
  {
   "cell_type": "code",
   "execution_count": null,
   "id": "914969b2",
   "metadata": {},
   "outputs": [],
   "source": []
  }
 ],
 "metadata": {
  "kernelspec": {
   "display_name": "Python 3 (ipykernel)",
   "language": "python",
   "name": "python3"
  },
  "language_info": {
   "codemirror_mode": {
    "name": "ipython",
    "version": 3
   },
   "file_extension": ".py",
   "mimetype": "text/x-python",
   "name": "python",
   "nbconvert_exporter": "python",
   "pygments_lexer": "ipython3",
   "version": "3.9.13"
  }
 },
 "nbformat": 4,
 "nbformat_minor": 5
}
